<?xml version="1.0" encoding="utf-8"?>
<!-- This URDF was automatically created by SolidWorks to URDF Exporter! Originally created by Stephen Brawner (brawner@gmail.com) 
     Commit Version: 1.5.1-0-g916b5db  Build Version: 1.5.7152.31018
     For more information, please see http://wiki.ros.org/sw_urdf_exporter -->
<robot
  name="robotti_1">
  <link
    name="base_link">
    <inertial>
      <origin
        xyz="-0.19471 0.00063105 0.090181"
        rpy="0 0 0" />
      <mass
        value="8.7074" />
      <inertia
        ixx="0.03503"
        ixy="5.3268E-07"
        ixz="-0.00016399"
        iyy="0.012664"
        iyz="4.135E-08"
        izz="0.042878" />
    </inertial>
    <visual>
      <origin
        xyz="0 0 0"
        rpy="0 0 0" />
      <geometry>
        <mesh
          filename="package://robotti_1/meshes/base_link.STL" />
      </geometry>
      <material
        name="">
        <color
          rgba="0.75294 0.75294 0.75294 1" />
      </material>
    </visual>
    <collision>
      <origin
        xyz="0 0 0"
        rpy="0 0 0" />
      <geometry>
        <mesh
          filename="package://robotti_1/meshes/base_hitbox.STL" />
      </geometry>
    </collision>
  </link>
  <link
    name="l_wheel_link">
    <inertial>
      <origin
        xyz="2.9698E-05 -0.0045616 -1.6964E-05"
        rpy="0 0 0" />
      <mass
        value="1.4926" />
      <inertia
        ixx="0.0047081"
        ixy="9.1511E-12"
        ixz="-4.8794E-09"
        iyy="0.0086484"
        iyz="1.6021E-11"
        izz="0.0047081" />
    </inertial>
    <visual>
      <origin
        xyz="0 0 0"
        rpy="0 0 0" />
      <geometry>
        <mesh
          filename="package://robotti_1/meshes/l_wheel_link.STL" />
      </geometry>
      <material
        name="">
        <color
          rgba="0.83137 0.83922 0.83137 1" />
      </material>
    </visual>
    <collision>
      <origin
        xyz="0 0 0"
        rpy="0 0 0" />
      <geometry>
        <mesh
          filename="package://robotti_1/meshes/l_wheel_link.STL" />
      </geometry>
    </collision>
  </link>
  <joint
    name="l_wheel_joint"
    type="continuous">
    <origin
      xyz="-0.20582 0.19763 0.099"
      rpy="0 0 0" />
    <parent
      link="base_link" />
    <child
      link="l_wheel_link" />
    <axis
      xyz="0 -1 0" />
  </joint>
  <link
    name="r_wheel_link">
    <inertial>
      <origin
        xyz="1.039E-05 -0.0045616 -3.2585E-05"
        rpy="0 0 0" />
      <mass
        value="1.4926" />
      <inertia
        ixx="0.0047081"
        ixy="1.7578E-11"
        ixz="-3.279E-09"
        iyy="0.0086484"
        iyz="5.6048E-12"
        izz="0.0047081" />
    </inertial>
    <visual>
      <origin
        xyz="0 0 0"
        rpy="0 0 0" />
      <geometry>
        <mesh
          filename="package://robotti_1/meshes/r_wheel_link.STL" />
      </geometry>
      <material
        name="">
        <color
          rgba="0.83137 0.83922 0.83137 1" />
      </material>
    </visual>
    <collision>
      <origin
        xyz="0 0 0"
        rpy="0 0 0" />
      <geometry>
        <mesh
          filename="package://robotti_1/meshes/r_wheel_link.STL" />
      </geometry>
    </collision>
  </link>
  <joint
    name="r_wheel_joint"
    type="continuous">
    <origin
      xyz="-0.20582 -0.18936 0.099"
      rpy="0 0 0" />
    <parent
      link="base_link" />
    <child
      link="r_wheel_link" />
    <axis
      xyz="0 -1 0" />
  </joint>
  <link
    name="weapon_link">
    <inertial>
      <origin
        xyz="-2.387E-15 -1.1102E-15 0.024839"
        rpy="0 0 0" />
      <mass
        value="0.067649" />
      <inertia
        ixx="4.6255E-05"
        ixy="-4.4117E-10"
        ixz="2.2164E-19"
        iyy="4.6255E-05"
        iyz="9.9394E-20"
        izz="1.6891E-05" />
    </inertial>
    <visual>
      <origin
        xyz="0 0 0"
        rpy="0 0 0" />
      <geometry>
        <mesh
          filename="package://robotti_1/meshes/weapon_link.STL" />
      </geometry>
      <material
        name="">
        <color
          rgba="0.75294 0.75294 0.75294 1" />
      </material>
    </visual>
    <collision>
      <origin
        xyz="0 0 0"
        rpy="0 0 0" />
      <geometry>
        <mesh
          filename="package://robotti_1/meshes/weapon_link.STL" />
      </geometry>
    </collision>
  </link>
  <joint
    name="weapon_joint"
    type="fixed">
    <origin
      xyz="0.01418 0.001 0.08"
      rpy="0 0 0" />
    <parent
      link="base_link" />
    <child
      link="weapon_link" />
    <axis
      xyz="0 0 0" />
  </joint>
  <link
    name="weapon_blade_link">
    <inertial>
      <origin
        xyz="2.9421E-15 -2.3037E-15 0.004"
        rpy="0 0 0" />
      <mass
        value="1.9334" />
      <inertia
        ixx="0.0095088"
        ixy="1.0612E-16"
        ixz="3.255E-16"
        iyy="0.0095088"
        iyz="1.1268E-16"
        izz="0.018997" />
    </inertial>
    <visual>
      <origin
        xyz="0 0 0"
        rpy="0 0 0" />
      <geometry>
        <mesh
          filename="package://robotti_1/meshes/weapon_blade_link.STL" />
      </geometry>
      <material
        name="">
        <color
          rgba="1 0 0 1" />
      </material>
    </visual>
    <collision>
      <origin
        xyz="0 0 0"
        rpy="0 0 0" />
      <geometry>
        <mesh
          filename="package://robotti_1/meshes/weapon_blade_hitbox.STL" />
      </geometry>
    </collision>
  </link>
  <joint
    name="weapon_blade_joint"
    type="continuous">
    <origin
      xyz="0 0 0"
      rpy="0 0 0" />
    <parent
      link="weapon_link" />
    <child
      link="weapon_blade_link" />
    <axis
      xyz="0 0 1" />
  </joint>

  <transmission name="tran_left_wheel">
    <type>transmission_interface/SimpleTransmission</type>
    <joint name="l_wheel_joint">
      <hardwareInterface>hardware_interface/VelocityJointInterface</hardwareInterface>
    </joint>
    <actuator name="robot1_left_wheel">
      <hardwareInterface>hardware_interface/VelocityJointInterface</hardwareInterface>
      <mechanicalReduction>1</mechanicalReduction>
    </actuator>
  </transmission>

  <transmission name="tran_left_wheel">
    <type>transmission_interface/SimpleTransmission</type>
    <joint name="r_wheel_joint">
      <hardwareInterface>VelocityJointInterface</hardwareInterface>
    </joint>
    <actuator name="robot1_left_wheel">
      <hardwareInterface>VelocityJointInterface</hardwareInterface>
      <mechanicalReduction>1</mechanicalReduction>
    </actuator>
  </transmission>

  <transmission name="weapon_joint">
    <type>transmission_interface/SimpleTransmission</type>
    <joint name="weapon_blade_joint">
      <hardwareInterface>VelocityJointInterface</hardwareInterface>
    </joint>
    <actuator name="robot1_weapon_actuator">
      <hardwareInterface>VelocityJointInterface</hardwareInterface>
      <mechanicalReduction>1</mechanicalReduction>
    </actuator>
  </transmission>

  <gazebo>
    <plugin name="gazebo_ros_control" filename="libgazebo_ros_control.so">
      <!--<robotNamespace>/robot1</robotNamespace>-->
    </plugin>
  </gazebo>

  <gazebo reference="camera_link">

		<material>Gazebo/Blue</material>

  	</gazebo>

  	<joint name="camera_joint" type="fixed">

			<origin rpy="0 0 0" xyz="0 0 0.01"/>

			<child link="camera_link"/>

			<parent link="base_link"/>

	</joint>

  

  	<link name="camera_link">

		<collision>

		</collision>

		<!--
		 <collision>
			 <origin xyz="0 0 0" rpy="0 0 0" />
			 <geometry>
				 <box size="0.05 0.03 0.007"/>
			 </geometry>
		 </collision>
		 <visual>
			 <origin xyz="0 0 0" rpy="0 0 0" />
			 <geometry>
				 <box size="0.05 0.03 0.007"/>
			 </geometry>
			 <material name="grey">
					 <color rgba="0.2 0.2 0.2 1.0"/>
			 </material>
		 </visual>
		 <inertial>
			 <mass value="0.001" />
			 <origin xyz="0 0 0" rpy="0 0 0" />
			 <inertia ixx="0.0001" ixy="0" ixz="0" iyy="0.0001" iyz="0" izz="0.0001" />
		 </inertial>
	 -->

	</link>



  	<gazebo reference="camera_link">

		 <sensor type="camera" name="camera_camera_sensor">

			 <update_rate>30.0</update_rate>

			 <camera name="head">

				 <!--<pose>0.035 0 0.078 0 0 0</pose> -->

				 <horizontal_fov>1.34</horizontal_fov>

				 <image>

					 <!--<format>R8G8B8</format>-->

					 <!---<width>1020</width>
					 <height>1020</height>-->

					 <!--change to smaaler resolution-->

					 <format>L8</format><!--change to greyscale format-->

					 <!--change to smaaler resolution-->

					 <width>320</width>

					 <height>240</height>

				 </image>

				 <clip>

					 <near>0.01</near>

					 <far>100</far>

				 </clip>

			 </camera>



			 <plugin name="camera_controller" filename="libgazebo_ros_camera.so">

				 <alwaysOn>true</alwaysOn>

				 <updateRate>0.0</updateRate>

				 <cameraName>head</cameraName>

				 <imageTopicName>image_raw</imageTopicName>

				 <cameraInfoTopicName>camera_info</cameraInfoTopicName>

				 <frameName>camera_link</frameName>

				 <hackBaseline>0.07</hackBaseline>

				 <distortionK1>0.0</distortionK1>

				 <distortionK2>0.0</distortionK2>

				 <distortionK3>0.0</distortionK3>

				 <distortionT1>0.0</distortionT1>

				 <distortionT2>0.0</distortionT2>

			 </plugin>

		 </sensor>

	</gazebo>

  <link name="sonic1_link"><collision></collision></link>

	 <joint name="sonic1_joint" type="fixed">

					
			<origin rpy="0 0 0.6" xyz="0.006 0.08 0.1375"/>

			<child link="sonic1_link"/>

			<parent link="base_link"/>

	 </joint>

	 <gazebo reference="sonic1_link">

		 <sensor type="ray" name="sonic1_sensor">

			 <pose>0 0 0 0 0 0</pose>

			 <update_rate>60</update_rate>

			 <visualize>true</visualize>

			 <ray>

				  <scan>

						 <horizontal>

							 <samples>5</samples>

							 <resolution>1.0</resolution>

							 <min_angle>-0.05</min_angle>

							 <max_angle>0.05</max_angle>

						 </horizontal>

						 <vertical>

							 <samples>1</samples>

							 <resolution>1</resolution>

							 <min_angle>-0.05</min_angle>

							 <max_angle>0.05</max_angle>

						 </vertical>

					 </scan>

				 <range>

					 <min>0.01</min>

					 <max>5</max>

					 <resolution>0.01</resolution>

					
				 </range>

			 </ray>

			 <plugin name="sonic1_controller" filename="libgazebo_ros_range.so">

				 <gaussianNoise>0.005</gaussianNoise>

				 <alwaysOn>true</alwaysOn>

				 <updateRate>60</updateRate>

				 <topicName>/ultrasonic1</topicName>

				 <frameName>sonic1_link</frameName>

				 <minRange>0.01</minRange>

				 <maxRange>5</maxRange>

				 <fov>0.5</fov>

				 <radiation>ultrasound</radiation>

			 </plugin>

		 </sensor>

	 </gazebo>


   <link name="sonic2_link"><collision></collision></link>

	 <joint name="sonic2_joint" type="fixed">

			<origin rpy="0 0 -0.6" xyz="-0.006 -0.08 0.1375"/>

			<child link="sonic2_link"/>

			<parent link="base_link"/>

	 </joint>

	 <gazebo reference="sonic2_link">

		 <sensor type="ray" name="sonic2_sensor">

			 <pose>0 0 0 0 0 0</pose>

			 <update_rate>60</update_rate>

			 <visualize>true</visualize>

			 <ray>

				 <scan>

						 <horizontal>

							 <samples>5</samples>

							 <resolution>1.0</resolution>

							 <min_angle>-0.05</min_angle>

							 <max_angle>0.05</max_angle>

						 </horizontal>

						 <vertical>

							 <samples>1</samples>

							 <resolution>1</resolution>

							 <min_angle>-0.05</min_angle>

							 <max_angle>0.05</max_angle>

						 </vertical>

					 </scan>

				 <range>

					 <min>0.01</min>

					 <max>5</max>

					 <resolution>0.01</resolution>

				 </range>

			 </ray>

			 <plugin name="sonic2_controller" filename="libgazebo_ros_range.so">

				 <gaussianNoise>0.005</gaussianNoise>

				 <alwaysOn>true</alwaysOn>

				 <updateRate>60</updateRate>

				 <topicName>/ultrasonic2</topicName>
				 <frameName>sonic2_link</frameName>
				 <minRange>0.01</minRange>
				 <maxRange>5</maxRange>
				 <fov>0.5</fov>
				 <radiation>ultrasound</radiation>
			 </plugin>
		 </sensor>
	 </gazebo>

   <link name="sonic3_link"><collision></collision></link>
	 <joint name="sonic3_joint" type="fixed">
			<origin rpy="0 0 3.1" xyz="-0.315 0.125 0.1"/>
			<child link="sonic3_link"/>
			<parent link="base_link"/>
	 </joint>

	 <gazebo reference="sonic3_link">
		 <sensor type="ray" name="sonic3_sensor">
			 <pose>0 0 0 0 0 0</pose>
			 <update_rate>60</update_rate>
			 <visualize>true</visualize>
			 <ray>
				 <scan>
						 <horizontal>
							 <samples>5</samples>
							 <resolution>1.0</resolution>
							 <min_angle>-0.05</min_angle>
							 <max_angle>0.05</max_angle>
						 </horizontal>
						 <vertical>
							 <samples>1</samples>
							 <resolution>1</resolution>
							 <min_angle>-0.05</min_angle>
							 <max_angle>0.05</max_angle>
						 </vertical>
					 </scan>
				 <range>
					 <min>0.01</min>
					 <max>5</max>
					 <resolution>0.01</resolution>
				 </range>
			 </ray>
			 <plugin name="sonic3_controller" filename="libgazebo_ros_range.so">
				 <gaussianNoise>0.005</gaussianNoise>
				 <alwaysOn>true</alwaysOn>
				 <updateRate>60</updateRate>
				 <topicName>/ultrasonic3</topicName>
				 <frameName>sonic3_link</frameName>
				 <minRange>0.01</minRange>
				 <maxRange>5</maxRange>
				 <fov>0.5</fov>
				 <radiation>ultrasound</radiation>
			 </plugin>
		 </sensor>
	 </gazebo>
    <link name="sonic4_link"><collision></collision></link>
	 <joint name="sonic4_joint" type="fixed">
			<origin rpy="0 0 3.1" xyz="-0.315 -0.125 0.1"/>
			<child link="sonic4_link"/>
			<parent link="base_link"/>
	 </joint>

	 <gazebo reference="sonic4_link">
		 <sensor type="ray" name="sonic4_sensor">
			 <pose>0 0 0 0 0 0</pose>
			 <update_rate>60</update_rate>
			 <visualize>true</visualize>
			 <ray>
				 <scan>
						 <horizontal>
							 <samples>5</samples>
							 <resolution>1.0</resolution>
							 <min_angle>-0.05</min_angle>
							 <max_angle>0.05</max_angle>
						 </horizontal>
						 <vertical>
							 <samples>1</samples>
							 <resolution>1</resolution>
							 <min_angle>-0.05</min_angle>
							 <max_angle>0.05</max_angle>
						 </vertical>
					 </scan>
				 <range>
					 <min>0.01</min>
					 <max>5</max>
					 <resolution>0.01</resolution>
				 </range>
			 </ray>
			 <plugin name="sonic4_controller" filename="libgazebo_ros_range.so">
				 <gaussianNoise>0.005</gaussianNoise>
				 <alwaysOn>true</alwaysOn>
				 <updateRate>60</updateRate>
				 <topicName>/ultrasonic4</topicName>
				 <frameName>sonic4_link</frameName>
				 <minRange>0.01</minRange>
				 <maxRange>5</maxRange>
				 <fov>0.5</fov>
				 <radiation>ultrasound</radiation>
			 </plugin>
		 </sensor>
	 </gazebo>
    <link name="sonic5_link"><collision></collision></link>
	 <joint name="sonic5_joint" type="fixed">
			<origin rpy="0 0 4.65" xyz="-0.215 -0.25 0.1"/>
			<child link="sonic5_link"/>
			<parent link="base_link"/>
	 </joint>

	 <gazebo reference="sonic5_link">
		 <sensor type="ray" name="sonic5_sensor">
			 <pose>0 0 0 0 0 0</pose>
			 <update_rate>60</update_rate>
			 <visualize>true</visualize>
			 <ray>
				 <scan>
						 <horizontal>
							 <samples>5</samples>
							 <resolution>1.0</resolution>
							 <min_angle>-0.05</min_angle>
							 <max_angle>0.05</max_angle>
						 </horizontal>
						 <vertical>
							 <samples>1</samples>
							 <resolution>1</resolution>
							 <min_angle>-0.05</min_angle>
							 <max_angle>0.05</max_angle>
						 </vertical>
					 </scan>
				 <range>
					 <min>0.01</min>
					 <max>5</max>
					 <resolution>0.01</resolution>
				 </range>
			 </ray>
			 <plugin name="sonic5_controller" filename="libgazebo_ros_range.so">
				 <gaussianNoise>0.005</gaussianNoise>
				 <alwaysOn>true</alwaysOn>
				 <updateRate>60</updateRate>
				 <topicName>/ultrasonic5</topicName>
				 <frameName>sonic5_link</frameName>
				 <minRange>0.01</minRange>
				 <maxRange>5</maxRange>
				 <fov>0.5</fov>
				 <radiation>ultrasound</radiation>
			 </plugin>
		 </sensor>
	 </gazebo>

   <link name="sonic6_link"><collision></collision></link>
	 <joint name="sonic6_joint" type="fixed">
			<origin rpy="0 0 1.55" xyz="-0.215 0.25 0.1"/>
			<child link="sonic6_link"/>
			<parent link="base_link"/>
	 </joint>

	 <gazebo reference="sonic6_link">
		 <sensor type="ray" name="sonic6_sensor">
			 <pose>0 0 0 0 0 0</pose>
			 <update_rate>60</update_rate>
			 <visualize>true</visualize>
			 <ray>
				 <scan>
						 <horizontal>
							 <samples>5</samples>
							 <resolution>1.0</resolution>
							 <min_angle>-0.05</min_angle>
							 <max_angle>0.05</max_angle>
						 </horizontal>
						 <vertical>
							 <samples>1</samples>
							 <resolution>1</resolution>
							 <min_angle>-0.05</min_angle>
							 <max_angle>0.05</max_angle>
						 </vertical>
					 </scan>
				 <range>
					 <min>0.01</min>
					 <max>5</max>
					 <resolution>0.01</resolution>
				 </range>
			 </ray>

			 <plugin name="sonic6_controller" filename="libgazebo_ros_range.so">
				 <gaussianNoise>0.005</gaussianNoise>
				 <alwaysOn>true</alwaysOn>
				 <updateRate>60</updateRate>
				 <topicName>/ultrasonic6</topicName>
				 <frameName>sonic6_link</frameName>
				 <minRange>0.01</minRange>
				 <maxRange>5</maxRange>
				 <fov>0.5</fov>
				 <radiation>ultrasound</radiation>
			 </plugin>
		 </sensor>
	</gazebo>

  <gazebo reference="imu_link">
    <gravity>true</gravity>
    <sensor name="imu_sensor" type="imu">
      <always_on>true</always_on>
      <update_rate>100</update_rate>
      <visualize>true</visualize>
      <topic>__default_topic__</topic>
      <plugin filename="libgazebo_ros_imu_sensor.so" name="imu_plugin">
        <topicName>imu</topicName>
        <bodyName>imu_link</bodyName>
        <updateRateHZ>10.0</updateRateHZ>
        <gaussianNoise>0.0</gaussianNoise>
        <xyzOffset>0 0 0</xyzOffset>
        <rpyOffset>0 0 0</rpyOffset>
        <frameName>imu_link</frameName>
      </plugin>
      <pose>0 0 0 0 0 0</pose>
    </sensor>
  </gazebo>

  <link name="imu_link">

		<collision>
		</collision>
  </link>

  <joint name="imu_joint" type="fixed">
			<origin rpy="0 0 0" xyz="0 0 0"/>
			<child link="imu_link"/>
	<parent link="base_link"/>
	</joint>

  <gazebo>
    <plugin name="robo1_base_controller" filename="libgazebo_ros_p3d.so">
      <alwaysOn>true</alwaysOn>
      <updateRate>60.0</updateRate>
      <bodyName>base_link</bodyName>
      <topicName>odom</topicName>
      <gaussianNoise>0.01</gaussianNoise>
      <frameName>map</frameName>
      <xyzOffsets>0 0 0</xyzOffsets>
      <rpyOffsets>0 0 0</rpyOffsets>
    </plugin>
  </gazebo>

</robot>
